Workbook
Name Slicer_Date_Hierarchy: #N/A
Name Slicer_month_name1: #N/A
Name Slicer_status: #N/A

Sheet EDA
A1: Row Labels | B1: Total Revenue | C1: Total Transactions | E1: Total Revenue | F1: Total Transactions | G1: Success Rate | H1: Avg. Transaction Value | J1: Total Merchants | K1: Total Users | M1: Success Rate
A2: Jan | B2: 53197384 | C2: 4141 | E2: 619200237 | F2: 48631 | G2: 0.51 | H2: 12732.62 | J2: 500 | K2: 5000 | M2: 0.51
A3: Feb | B3: 49011282 | C3: 3765
A4: Mar | B4: 52216249 | C4: 4171
A5: Apr | B5: 49592736 | C5: 4002 | E5: vs RPY | F5: vs TPY | G5: vs APY
A6: May | B6: 51961649 | C6: 4125 | E6: vs PY +0%↑ | F6: vs PY +0%↑ | G6: vs PY +0%↑
A7: Jun | B7: 51584875 | C7: 4178
A8: Jul | B8: 50246530 | C8: 4074
A9: Aug | B9: 53475566 | C9: 4189
A10: Sep | B10: 51035143 | C10: 3970 | E10: Row Labels | F10: Total Revenue | G10: Total Transactions
A11: Oct | B11: 51028184 | C11: 4004 | E11: Jan | F11: 53197384 | G11: 4141
A12: Nov | B12: 52210913 | C12: 3953 | E12: Feb | F12: 49011282 | G12: 3765
A13: Dec | B13: 53639726 | C13: 4059 | E13: Mar | F13: 52216249 | G13: 4171
E14: Apr | F14: 49592736 | G14: 4002
E15: May | F15: 51961649 | G15: 4125
A16: Row Labels | B16: Total Transactions | E16: Jun | F16: 51584875 | G16: 4178
A17: Success | B17: 24700 | E17: Jul | F17: 50246530 | G17: 4074
A18: Pending | B18: 11979 | E18: Aug | F18: 53475566 | G18: 4189
A19: Failed | B19: 11952 | E19: Sep | F19: 51035143 | G19: 3970
E20: Oct | F20: 51028184 | G20: 4004
E21: Nov | F21: 52210913 | G21: 3953
A22: Row Labels | B22: Total Revenue2 | C22: Total Revenue | E22: Dec | F22: 53639726 | G22: 4059
A23: Low Value | B23: 99644352 | C23: 0.16092428
A24: Mid Value | B24: 195579363 | C24: 0.31585802
A25: High Value | B25: 323976522 | C25: 0.5232177
A28: Row Labels | B28: Total Revenue
A29: Foster- Waters and Martinez | B29: 1780247
A30: Reynolds- Velez and Sweeney | B30: 1922115
A31: Taylor PLC | B31: 2152642
A32: Brown Group | B32: 2238423
A33: Wood Inc | B33: 2272078
A34: Scott PLC | B34: 2297365
A35: Brown Ltd | B35: 2531119
A36: Williams Group | B36: 2591740
A37: Adams Ltd | B37: 2630352
A38: Alvarez PLC | B38: 2850187
A42: Row Labels | B42: Total Transactions | C42: Total Transactions2
A43: USSD | B43: 12110 | C43: 0.33234535
A44: Card | B44: 12136 | C44: 0.33305889
A45: Transfer | B45: 12192 | C45: 0.33459575
...

Sheet EDA2
A3: Month | B3: Revenue | C3: Transactions | D3: Cursor V | E3: Cursor B
A4: Jan | B4: =GETPIVOTDATA("[Measures].[Total Revenue]",EDA!$A$1,"[Calendar].[Month-abb]","[Calendar].[Month-abb].&[" & $A4 & "]") -> 53197384 | C4: =GETPIVOTDATA("[Measures].[Total Transactions]",EDA!$A$1,"[Calendar].[Month-abb]","[Calendar].[Month-abb].&[" & $A4 & "]") -> 4141 | D4: =IFERROR(GETPIVOTDATA("[Measures].[Total Revenue]",EDA!$E$10,"[Calendar].[Month-abb]","[Calendar].[Month-abb].&[" & $A4 & "]"), NA()) -> 53197384 | E4: =IFERROR(GETPIVOTDATA("[Measures].[Total Transactions]",EDA!$E$10,"[Calendar].[Month-abb]","[Calendar].[Month-abb].&[" & $A4 & "]"),"") -> 4141
A5: Feb | B5: =GETPIVOTDATA("[Measures].[Total Revenue]",EDA!$A$1,"[Calendar].[Month-abb]","[Calendar].[Month-abb].&[" & $A5 & "]") -> 49011282 | C5: =GETPIVOTDATA("[Measures].[Total Transactions]",EDA!$A$1,"[Calendar].[Month-abb]","[Calendar].[Month-abb].&[" & $A5 & "]") -> 3765 | D5: =IFERROR(GETPIVOTDATA("[Measures].[Total Revenue]",EDA!$E$10,"[Calendar].[Month-abb]","[Calendar].[Month-abb].&[" & $A5 & "]"), NA()) -> 49011282 | E5: =IFERROR(GETPIVOTDATA("[Measures].[Total Transactions]",EDA!$E$10,"[Calendar].[Month-abb]","[Calendar].[Month-abb].&[" & $A5 & "]"),"") -> 3765
A6: Mar | B6: =GETPIVOTDATA("[Measures].[Total Revenue]",EDA!$A$1,"[Calendar].[Month-abb]","[Calendar].[Month-abb].&[" & $A6 & "]") -> 52216249 | C6: =GETPIVOTDATA("[Measures].[Total Transactions]",EDA!$A$1,"[Calendar].[Month-abb]","[Calendar].[Month-abb].&[" & $A6 & "]") -> 4171 | D6: =IFERROR(GETPIVOTDATA("[Measures].[Total Revenue]",EDA!$E$10,"[Calendar].[Month-abb]","[Calendar].[Month-abb].&[" & $A6 & "]"), NA()) -> 52216249 | E6: =IFERROR(GETPIVOTDATA("[Measures].[Total Transactions]",EDA!$E$10,"[Calendar].[Month-abb]","[Calendar].[Month-abb].&[" & $A6 & "]"),"") -> 4171
A7: Apr | B7: =GETPIVOTDATA("[Measures].[Total Revenue]",EDA!$A$1,"[Calendar].[Month-abb]","[Calendar].[Month-abb].&[" & $A7 & "]") -> 49592736 | C7: =GETPIVOTDATA("[Measures].[Total Transactions]",EDA!$A$1,"[Calendar].[Month-abb]","[Calendar].[Month-abb].&[" & $A7 & "]") -> 4002 | D7: =IFERROR(GETPIVOTDATA("[Measures].[Total Revenue]",EDA!$E$10,"[Calendar].[Month-abb]","[Calendar].[Month-abb].&[" & $A7 & "]"), NA()) -> 49592736 | E7: =IFERROR(GETPIVOTDATA("[Measures].[Total Transactions]",EDA!$E$10,"[Calendar].[Month-abb]","[Calendar].[Month-abb].&[" & $A7 & "]"),"") -> 4002
A8: May | B8: =GETPIVOTDATA("[Measures].[Total Revenue]",EDA!$A$1,"[Calendar].[Month-abb]","[Calendar].[Month-abb].&[" & $A8 & "]") -> 51961649 | C8: =GETPIVOTDATA("[Measures].[Total Transactions]",EDA!$A$1,"[Calendar].[Month-abb]","[Calendar].[Month-abb].&[" & $A8 & "]") -> 4125 | D8: =IFERROR(GETPIVOTDATA("[Measures].[Total Revenue]",EDA!$E$10,"[Calendar].[Month-abb]","[Calendar].[Month-abb].&[" & $A8 & "]"), NA()) -> 51961649 | E8: =IFERROR(GETPIVOTDATA("[Measures].[Total Transactions]",EDA!$E$10,"[Calendar].[Month-abb]","[Calendar].[Month-abb].&[" & $A8 & "]"),"") -> 4125
A9: Jun | B9: =GETPIVOTDATA("[Measures].[Total Revenue]",EDA!$A$1,"[Calendar].[Month-abb]","[Calendar].[Month-abb].&[" & $A9 & "]") -> 51584875 | C9: =GETPIVOTDATA("[Measures].[Total Transactions]",EDA!$A$1,"[Calendar].[Month-abb]","[Calendar].[Month-abb].&[" & $A9 & "]") -> 4178 | D9: =IFERROR(GETPIVOTDATA("[Measures].[Total Revenue]",EDA!$E$10,"[Calendar].[Month-abb]","[Calendar].[Month-abb].&[" & $A9 & "]"), NA()) -> 51584875 | E9: =IFERROR(GETPIVOTDATA("[Measures].[Total Transactions]",EDA!$E$10,"[Calendar].[Month-abb]","[Calendar].[Month-abb].&[" & $A9 & "]"),"") -> 4178
A10: Jul | B10: =GETPIVOTDATA("[Measures].[Total Revenue]",EDA!$A$1,"[Calendar].[Month-abb]","[Calendar].[Month-abb].&[" & $A10 & "]") -> 50246530 | C10: =GETPIVOTDATA("[Measures].[Total Transactions]",EDA!$A$1,"[Calendar].[Month-abb]","[Calendar].[Month-abb].&[" & $A10 & "]") -> 4074 | D10: =IFERROR(GETPIVOTDATA("[Measures].[Total Revenue]",EDA!$E$10,"[Calendar].[Month-abb]","[Calendar].[Month-abb].&[" & $A10 & "]"), NA()) -> 50246530 | E10: =IFERROR(GETPIVOTDATA("[Measures].[Total Transactions]",EDA!$E$10,"[Calendar].[Month-abb]","[Calendar].[Month-abb].&[" & $A10 & "]"),"") -> 4074
A11: Aug | B11: =GETPIVOTDATA("[Measures].[Total Revenue]",EDA!$A$1,"[Calendar].[Month-abb]","[Calendar].[Month-abb].&[" & $A11 & "]") -> 53475566 | C11: =GETPIVOTDATA("[Measures].[Total Transactions]",EDA!$A$1,"[Calendar].[Month-abb]","[Calendar].[Month-abb].&[" & $A11 & "]") -> 4189 | D11: =IFERROR(GETPIVOTDATA("[Measures].[Total Revenue]",EDA!$E$10,"[Calendar].[Month-abb]","[Calendar].[Month-abb].&[" & $A11 & "]"), NA()) -> 53475566 | E11: =IFERROR(GETPIVOTDATA("[Measures].[Total Transactions]",EDA!$E$10,"[Calendar].[Month-abb]","[Calendar].[Month-abb].&[" & $A11 & "]"),"") -> 4189
A12: Sep | B12: =GETPIVOTDATA("[Measures].[Total Revenue]",EDA!$A$1,"[Calendar].[Month-abb]","[Calendar].[Month-abb].&[" & $A12 & "]") -> 51035143 | C12: =GETPIVOTDATA("[Measures].[Total Transactions]",EDA!$A$1,"[Calendar].[Month-abb]","[Calendar].[Month-abb].&[" & $A12 & "]") -> 3970 | D12: =IFERROR(GETPIVOTDATA("[Measures].[Total Revenue]",EDA!$E$10,"[Calendar].[Month-abb]","[Calendar].[Month-abb].&[" & $A12 & "]"), NA()) -> 51035143 | E12: =IFERROR(GETPIVOTDATA("[Measures].[Total Transactions]",EDA!$E$10,"[Calendar].[Month-abb]","[Calendar].[Month-abb].&[" & $A12 & "]"),"") -> 3970
A13: Oct | B13: =GETPIVOTDATA("[Measures].[Total Revenue]",EDA!$A$1,"[Calendar].[Month-abb]","[Calendar].[Month-abb].&[" & $A13 & "]") -> 51028184 | C13: =GETPIVOTDATA("[Measures].[Total Transactions]",EDA!$A$1,"[Calendar].[Month-abb]","[Calendar].[Month-abb].&[" & $A13 & "]") -> 4004 | D13: =IFERROR(GETPIVOTDATA("[Measures].[Total Revenue]",EDA!$E$10,"[Calendar].[Month-abb]","[Calendar].[Month-abb].&[" & $A13 & "]"), NA()) -> 51028184 | E13: =IFERROR(GETPIVOTDATA("[Measures].[Total Transactions]",EDA!$E$10,"[Calendar].[Month-abb]","[Calendar].[Month-abb].&[" & $A13 & "]"),"") -> 4004
A14: Nov | B14: =GETPIVOTDATA("[Measures].[Total Revenue]",EDA!$A$1,"[Calendar].[Month-abb]","[Calendar].[Month-abb].&[" & $A14 & "]") -> 52210913 | C14: =GETPIVOTDATA("[Measures].[Total Transactions]",EDA!$A$1,"[Calendar].[Month-abb]","[Calendar].[Month-abb].&[" & $A14 & "]") -> 3953 | D14: =IFERROR(GETPIVOTDATA("[Measures].[Total Revenue]",EDA!$E$10,"[Calendar].[Month-abb]","[Calendar].[Month-abb].&[" & $A14 & "]"), NA()) -> 52210913 | E14: =IFERROR(GETPIVOTDATA("[Measures].[Total Transactions]",EDA!$E$10,"[Calendar].[Month-abb]","[Calendar].[Month-abb].&[" & $A14 & "]"),"") -> 3953
A15: Dec | B15: =GETPIVOTDATA("[Measures].[Total Revenue]",EDA!$A$1,"[Calendar].[Month-abb]","[Calendar].[Month-abb].&[" & $A15 & "]") -> 53639726 | C15: =GETPIVOTDATA("[Measures].[Total Transactions]",EDA!$A$1,"[Calendar].[Month-abb]","[Calendar].[Month-abb].&[" & $A15 & "]") -> 4059 | D15: =IFERROR(GETPIVOTDATA("[Measures].[Total Revenue]",EDA!$E$10,"[Calendar].[Month-abb]","[Calendar].[Month-abb].&[" & $A15 & "]"), NA()) -> 53639726 | E15: =IFERROR(GETPIVOTDATA("[Measures].[Total Transactions]",EDA!$E$10,"[Calendar].[Month-abb]","[Calendar].[Month-abb].&[" & $A15 & "]"),"") -> 4059
D16: =GETPIVOTDATA("[Measures].[Total Revenue]",EDA!$E$1) -> 619200237 | E16: =GETPIVOTDATA("[Measures].[Total Transactions]",EDA!$E$1) -> 48631
A18: User Value | B18: Total Revenue % | C18: % | D18: Indent
A19: {=EDA!A23:A25} -> Low Value | B19: {=EDA!C23:C25} -> 0.16092428 | C19: =100%-B19 -> 0.83907572 | D19: =$D$22 -> 0.023
A20: Mid Value | B20: 0.31585802 | C20: =100%-B20 -> 0.68414198 | D20: =$D$22 -> 0.023
A21: High Value | B21: 0.5232177 | C21: =100%-B21 -> 0.4767823 | D21: =$D$22 -> 0.023
D22: 0.023
A24: Merchants | B24: Revenue
A25: {=EDA!A29:A38} -> Foster- Waters and Martinez | B25: {=EDA!B29:B38} -> 1780247 | C25: ='EDA2'!$D$22 -> 0.023 | E25: =(SUM(_xlfn.ANCHORARRAY(B25)))/D16 -> 0.037574708
A26: Reynolds- Velez and Sweeney | B26: 1922115 | C26: ='EDA2'!$D$22 -> 0.023
A27: Taylor PLC | B27: 2152642 | C27: ='EDA2'!$D$22 -> 0.023
A28: Brown Group | B28: 2238423 | C28: ='EDA2'!$D$22 -> 0.023
A29: Wood Inc | B29: 2272078 | C29: ='EDA2'!$D$22 -> 0.023
A30: Scott PLC | B30: 2297365 | C30: ='EDA2'!$D$22 -> 0.023
A31: Brown Ltd | B31: 2531119 | C31: ='EDA2'!$D$22 -> 0.023
A32: Williams Group | B32: 2591740 | C32: ='EDA2'!$D$22 -> 0.023
A33: Adams Ltd | B33: 2630352 | C33: ='EDA2'!$D$22 -> 0.023
A34: Alvarez PLC | B34: 2850187 | C34: ='EDA2'!$D$22 -> 0.023
A37: Paynent Method | B37: Transaction% | D37: Indent
A38: {=EDA!A43:A45} -> USSD | B38: {=EDA!C43:C45} -> 0.33234535 | C38: {=100%-_xlfn.ANCHORARRAY(B38)} -> 0.66765465 | D38: =$D$41 -> 0.023
A39: Card | B39: 0.33305889 | C39: 0.66694111 | D39: =$D$41 -> 0.023
A40: Transfer | B40: 0.33459575 | C40: 0.66540425 | D40: =$D$41 -> 0.023
D41: 0.023

Sheet Sheet1

Sheet Home

Sheet Monthly Trend

Sheet Merchants

Sheet Status

Sheet User Segment

Sheet Channels
